<?xml version="1.0" encoding="UTF-8"?>
<testng-results skipped="0" failed="1" total="3" passed="2">
  <reporter-output>
  </reporter-output>
  <suite name="Suite" duration-ms="172" started-at="2016-09-07T12:21:08Z" finished-at="2016-09-07T12:21:08Z">
    <groups>
    </groups>
    <test name="Test" duration-ms="172" started-at="2016-09-07T12:21:08Z" finished-at="2016-09-07T12:21:08Z">
      <class name="Newpackage.NewTest">
        <test-method status="PASS" signature="testcase1()[pri:0, instance:Newpackage.NewTest@73ad2d6]" name="testcase1" duration-ms="47" started-at="2016-09-07T17:51:08Z" finished-at="2016-09-07T17:51:08Z">
          <reporter-output>
          </reporter-output>
        </test-method> <!-- testcase1 -->
        <test-method status="FAIL" signature="testcase2()[pri:0, instance:Newpackage.NewTest@73ad2d6]" name="testcase2" duration-ms="16" started-at="2016-09-07T17:51:08Z" finished-at="2016-09-07T17:51:08Z">
          <exception class="java.lang.AssertionError">
            <message>
              <![CDATA[expected [true] but found [false]]]>
            </message>
            <full-stacktrace>
              <![CDATA[java.lang.AssertionError: expected [true] but found [false]
	at org.testng.Assert.fail(Assert.java:94)
	at org.testng.Assert.failNotEquals(Assert.java:494)
	at org.testng.Assert.assertTrue(Assert.java:42)
	at org.testng.Assert.assertTrue(Assert.java:52)
	at Newpackage.NewTest.testcase2(NewTest.java:14)
	at sun.reflect.NativeMethodAccessorImpl.invoke0(Native Method)
	at sun.reflect.NativeMethodAccessorImpl.invoke(Unknown Source)
	at sun.reflect.DelegatingMethodAccessorImpl.invoke(Unknown Source)
	at java.lang.reflect.Method.invoke(Unknown Source)
	at org.testng.internal.MethodInvocationHelper.invokeMethod(MethodInvocationHelper.java:84)
	at org.testng.internal.Invoker.invokeMethod(Invoker.java:714)
	at org.testng.internal.Invoker.invokeTestMethod(Invoker.java:901)
	at org.testng.internal.Invoker.invokeTestMethods(Invoker.java:1231)
	at org.testng.internal.TestMethodWorker.invokeTestMethods(TestMethodWorker.java:127)
	at org.testng.internal.TestMethodWorker.run(TestMethodWorker.java:111)
	at org.testng.TestRunner.privateRun(TestRunner.java:767)
	at org.testng.TestRunner.run(TestRunner.java:617)
	at org.testng.SuiteRunner.runTest(SuiteRunner.java:348)
	at org.testng.SuiteRunner.runSequentially(SuiteRunner.java:343)
	at org.testng.SuiteRunner.privateRun(SuiteRunner.java:305)
	at org.testng.SuiteRunner.run(SuiteRunner.java:254)
	at org.testng.SuiteRunnerWorker.runSuite(SuiteRunnerWorker.java:52)
	at org.testng.SuiteRunnerWorker.run(SuiteRunnerWorker.java:86)
	at org.testng.TestNG.runSuitesSequentially(TestNG.java:1224)
	at org.testng.TestNG.runSuitesLocally(TestNG.java:1149)
	at org.testng.TestNG.run(TestNG.java:1057)
	at org.testng.remote.AbstractRemoteTestNG.run(AbstractRemoteTestNG.java:126)
	at org.testng.remote.RemoteTestNG.initAndRun(RemoteTestNG.java:152)
	at org.testng.remote.RemoteTestNG.main(RemoteTestNG.java:57)
]]>
            </full-stacktrace>
          </exception> <!-- java.lang.AssertionError -->
          <reporter-output>
          </reporter-output>
        </test-method> <!-- testcase2 -->
        <test-method status="PASS" signature="testcase3()[pri:0, instance:Newpackage.NewTest@73ad2d6]" name="testcase3" duration-ms="15" started-at="2016-09-07T17:51:08Z" finished-at="2016-09-07T17:51:08Z">
          <reporter-output>
          </reporter-output>
        </test-method> <!-- testcase3 -->
      </class> <!-- Newpackage.NewTest -->
    </test> <!-- Test -->
  </suite> <!-- Suite -->
</testng-results>
